<?xml version="1.0"?>
<robot name="simple_robot">
  <link name="base_link">
    <visual>
      <geometry>
        <box size="0.6 1 0.05"/> 
      </geometry>
      <material name="grey">
          <color rgba="0.5 0.5 0.5 1"/>
      </material>
      <origin xyz="-0.3 0 -0.025" rpy="0 0 0"/>
    </visual>
    <collision>
      <geometry>
        <box size="0.6 1 0.05"/>
      </geometry>
      <origin xyz="-0.3 0 -0.025" rpy="0 0 0"/>
    </collision>
  </link>

  <link name="laptop_lid_link">
    <visual>
      <geometry>
        <box size="0.6 1 0.05"/> 
      </geometry>
      <material name="grey">
          <color rgba="0.5 0.5 0.5 1"/>
      </material>
      <origin xyz="0.3 0 -0.025" rpy="0 0 0"/>
    </visual>
    <collision>
      <geometry>
        <box size="0.6 1 0.05"/>
      </geometry>
      <origin xyz="0.3 0 -0.025" rpy="0 0 0"/>
    </collision>
  </link>

  <link name="camera_link"></link>

  <joint name="laptop_hinge_joint" type="revolute">
    <parent link="base_link"/>
    <child link="laptop_lid_link"/>
    <origin xyz="0 0 0" rpy="0 3.14159 0"/>
    <axis xyz="0 1 0"/>  <!-- Rotation axis: y-axis -->
    <limit lower="-3.2" upper="3.2" effort="1000" velocity="0.5"/>
  </joint>

  <joint name="camera_joint" type="fixed">
    <parent link="laptop_lid_link"/>
    <child link="camera_link"/>
    <origin xyz="0.575 0 0" rpy="0 -1.570795 0"/>"
  </joint>
</robot>
